Traceback (most recent call last):
  File "/home/steffen/anaconda3/envs/rise/lib/python3.10/site-packages/jupyter_cache/executors/utils.py", line 58, in single_nb_execution
    executenb(
  File "/home/steffen/anaconda3/envs/rise/lib/python3.10/site-packages/nbclient/client.py", line 1319, in execute
    return NotebookClient(nb=nb, resources=resources, km=km, **kwargs).execute()
  File "/home/steffen/anaconda3/envs/rise/lib/python3.10/site-packages/jupyter_core/utils/__init__.py", line 165, in wrapped
    return loop.run_until_complete(inner)
  File "/home/steffen/anaconda3/envs/rise/lib/python3.10/asyncio/base_events.py", line 649, in run_until_complete
    return future.result()
  File "/home/steffen/anaconda3/envs/rise/lib/python3.10/site-packages/nbclient/client.py", line 709, in async_execute
    await self.async_execute_cell(
  File "/home/steffen/anaconda3/envs/rise/lib/python3.10/site-packages/nbclient/client.py", line 1062, in async_execute_cell
    await self._check_raise_for_error(cell, cell_index, exec_reply)
  File "/home/steffen/anaconda3/envs/rise/lib/python3.10/site-packages/nbclient/client.py", line 918, in _check_raise_for_error
    raise CellExecutionError.from_cell_and_msg(cell, exec_reply_content)
nbclient.exceptions.CellExecutionError: An error occurred while executing the following cell:
------------------
from  pyFEMEAH.Shapefunctions.ShapeFunctionQuad4 import ShapeFunctionQuad4 as SFQ4
import numpy as np
import plotly.graph_objects as go
from plotly.subplots import make_subplots

# Create a subplot with 1 row and 2 columns
fig = make_subplots(rows=2, cols=2, specs=[[{'type': 'scene'}, {'type': 'scene'}],
           [{'type': 'scene'}, {'type': 'scene'}]]  )

# Initialize your class
quads = SFQ4(2)
f1=quads.plot(1)
f2=quads.plot(2)
f3=quads.plot(3)
f4=quads.plot(4)

# Add the first plot to the first subplot
fig.add_trace(f1.data[0], row=1, col=1)
fig.add_trace(f2.data[0], row=1, col=2)
fig.add_trace(f3.data[0], row=2, col=1)
fig.add_trace(f4.data[0], row=2, col=2)


# Display the initial plot
figure.show()
------------------


[0;31m---------------------------------------------------------------------------[0m
[0;31mNameError[0m                                 Traceback (most recent call last)
Cell [0;32mIn[2], line 25[0m
[1;32m     21[0m fig[38;5;241m.[39madd_trace(f4[38;5;241m.[39mdata[[38;5;241m0[39m], row[38;5;241m=[39m[38;5;241m2[39m, col[38;5;241m=[39m[38;5;241m2[39m)
[1;32m     24[0m [38;5;66;03m# Display the initial plot[39;00m
[0;32m---> 25[0m [43mfigure[49m[38;5;241m.[39mshow()

[0;31mNameError[0m: name 'figure' is not defined

